<robot name="s2w" xmlns:xacro="http://ros.org/wiki/xacro">
    <link name="link_chassis">
        <pose> 0 0 0.1 0 0 0</pose>
        <inertial>
            <mass value="5"/>
            <inertia ixx="0.03954" ixy="0" ixz="0"
                     iyy="0.1062"  iyz="0" izz="0.1062"
            /></inertial>

        <collision name="collision_chassis">
            <geometry>
                <box size="0.5 0.3 0.07"/>
            </geometry>
        </collision>
        <visual>
            <geometry>
                <box size="0.5 0.3 0.07"/>
            </geometry>
        </visual>
        <collision name="collision_chassis_caster">
            <origin rpy="0 0 0" xyz="0.20 0 -0.05"/>
            <geometry>
                <sphere radius="0.05"/>
            </geometry>
            <surface>
                <friction>
                    <ode>
                        <mu>0</mu>
                        <mu2>0</mu2>
                        <slip1>1.0</slip1>
                        <slip2>1.0</slip2>
                    </ode>
                </friction>
            </surface>
        </collision>
        <visual name="visual_chassis_caster">
            <origin rpy="0 0 0" xyz="0.20 0 -0.05"/>
            <geometry>
                <sphere radius="0.05"/>
            </geometry>
        </visual>
    </link>
    <link name="link_right_wheel">
        <inertial>
            <mass value="0.2"/>
            <inertia ixx="0.0005266" ixy="0" ixz="0"
                     iyy="0.0005266"  iyz="0" izz="0.001"
        /></inertial>
        <collision name="collision_link_right_wheel">
            <geometry>
                <cylinder length="0.04" radius="0.1"/>
            </geometry>
        </collision>
        <visual name ="visual_right_wheel">
            <geometry>
                <cylinder length="0.04" radius="0.1"/>
            </geometry>
        </visual>
    </link>
    <joint name="joint_right_wheel" type="continuous">
        <origin rpy="1.5707 0 0" xyz="-0.05 0.15 0"/>
        <child link="link_right_wheel"/>
        <parent link="link_chassis"/>
        <axis rpy="0 0 0" xyz="0 0 1"/>
        <limit effort="10" velocity="10"/>
        <joint_properties damping="1.0" friction="1.0"/>
    </joint>
    <link name="link_left_wheel">
        <inertial>
            <mass value="0.2"/>
            <inertia ixx="0.0005266" ixy="0" ixz="0"
                     iyy="0.0005266"  iyz="0" izz="0.001"
        /></inertial>
        <collision name="collision_link_left_wheel">
            <geometry>
                <cylinder length="0.04" radius="0.1"/>
            </geometry>
        </collision>
        <visual name ="visual_left_wheel">
            <geometry>
                <cylinder length="0.04" radius="0.1"/>
            </geometry>
        </visual>
    </link>
    <joint name="joint_left_wheel" type="continuous">
        <origin rpy="1.5707 0 0" xyz="-0.05 -0.15 0"/>
        <child link="link_left_wheel"/>
        <child link="link_right_wheel"/>
        <parent link="link_chassis"/>
        <axis rpy="0 0 0" xyz="0 0 1"/>
        <limit effort="10" velocity="10"/>
        <joint_properties damping="1.0" friction="1.0"/>
    </joint>
</robot>